<sdf version='1.11'>
  <model name='ads_dv'>
    <link name='base_link'>
      <inertial>
        <pose>0 0 0 0 0 0</pose>
        <mass>0.001</mass>
        <inertia>
          <ixx>0.001</ixx>
          <ixy>0</ixy>
          <ixz>0</ixz>
          <iyy>0.001</iyy>
          <iyz>0</iyz>
          <izz>0.001</izz>
        </inertia>
      </inertial>
      <visual name='base_link_fixed_joint_lump__visual_visual'>
        <pose>0 0 0 0 0 0</pose>
        <geometry>
          <box>
            <size>0.01 0.01 0.01</size>
          </box>
        </geometry>
      </visual>
    </link>
    <joint name='base_to_camera' type='fixed'>
      <pose relative_to='base_link'>0.48649999999999999 0 0.67100000000000004 0 0 0</pose>
      <parent>base_link</parent>
      <child>camera_link</child>
      <axis>
        <dynamics>
          <spring_reference>0</spring_reference>
          <spring_stiffness>0</spring_stiffness>
        </dynamics>
        <xyz>0 0 1</xyz>
        <limit>
          <lower>-inf</lower>
          <upper>inf</upper>
        </limit>
      </axis>
      <physics>
        <ode>
          <limit>
            <cfm>0</cfm>
            <erp>0.20000000000000001</erp>
          </limit>
        </ode>
      </physics>
    </joint>
    <link name='camera_link'>
      <pose relative_to='base_to_camera'>0 0 0 0 0 0</pose>
      <inertial>
        <pose>0 0 0 0 0 0</pose>
        <mass>0.001</mass>
        <inertia>
          <ixx>0.001</ixx>
          <ixy>0</ixy>
          <ixz>0</ixz>
          <iyy>0.001</iyy>
          <iyz>0</iyz>
          <izz>0.001</izz>
        </inertia>
      </inertial>
      <visual name='camera_link_fixed_joint_lump__visual_visual'>
        <pose>0 0 0 0 0 0</pose>
        <geometry>
          <box>
            <size>0.043099999999999999 0.17524999999999999 0.030249999999999999</size>
          </box>
        </geometry>
      </visual>
    </link>
    <joint name='camera_to_optical' type='fixed'>
      <pose relative_to='camera_link'>0 0 0 0 0 0</pose>
      <parent>camera_link</parent>
      <child>camera_link_optical</child>
      <axis>
        <dynamics>
          <spring_reference>0</spring_reference>
          <spring_stiffness>0</spring_stiffness>
        </dynamics>
        <xyz>0 0 1</xyz>
        <limit>
          <lower>-inf</lower>
          <upper>inf</upper>
        </limit>
      </axis>
      <physics>
        <ode>
          <limit>
            <cfm>0</cfm>
            <erp>0.20000000000000001</erp>
          </limit>
        </ode>
      </physics>
    </joint>
    <link name='camera_link_optical'>
      <pose relative_to='camera_to_optical'>0 0 0 0 0 0</pose>
      <inertial>
        <pose>0 0 0 0 0 0</pose>
        <mass>0.001</mass>
        <inertia>
          <ixx>0.001</ixx>
          <ixy>0</ixy>
          <ixz>0</ixz>
          <iyy>0.001</iyy>
          <iyz>0</iyz>
          <izz>0.001</izz>
        </inertia>
      </inertial>
      <sensor name='zed2i_depth_camera' type='rgbd_camera'>
        <update_rate>30</update_rate>
        <topic>zed2i/depth_camera</topic>
        <camera>
          <camera_info_topic>camera_info</camera_info_topic>
          <horizontal_fov>1.22173</horizontal_fov>
          <image>
            <width>640</width>
            <height>480</height>
            <format>R_FLOAT32</format>
          </image>
          <clip>
            <near>1.5</near>
            <far>35</far>
          </clip>
          <noise>
            <type>gaussian</type>
            <mean>0</mean>
            <stddev>0.0070000000000000001</stddev>
          </noise>
          <distortion>
            <k1>0</k1>
            <k2>0</k2>
            <k3>0</k3>
            <p1>0</p1>
            <p2>0</p2>
          </distortion>
        </camera>
        <gz_frame_id>camera_link_optical</gz_frame_id>
      </sensor>
    </link>
    <joint name='base_to_chassis' type='fixed'>
      <pose relative_to='base_link'>0 0 0.307 0 0 0</pose>
      <parent>base_link</parent>
      <child>chassis</child>
      <axis>
        <dynamics>
          <spring_reference>0</spring_reference>
          <spring_stiffness>0</spring_stiffness>
        </dynamics>
        <xyz>0 0 1</xyz>
        <limit>
          <lower>-inf</lower>
          <upper>inf</upper>
        </limit>
      </axis>
      <physics>
        <ode>
          <limit>
            <cfm>0</cfm>
            <erp>0.20000000000000001</erp>
          </limit>
        </ode>
      </physics>
    </joint>
    <link name='chassis'>
      <pose relative_to='base_to_chassis'>0 0 0 0 0 0</pose>
      <inertial>
        <pose>0 0 0 0 0 0</pose>
        <mass>278</mass>
        <inertia>
          <ixx>14.380000000000001</ixx>
          <ixy>0</ixy>
          <ixz>0</ixz>
          <iyy>178.90000000000001</iyy>
          <iyz>0</iyz>
          <izz>175.68000000000001</izz>
        </inertia>
      </inertial>
      <collision name='chassis_fixed_joint_lump__collision_collision'>
        <pose>0 0 0 0 0 0</pose>
        <geometry>
          <box>
            <size>2.7000000000000002 0.48899999999999999 0.41399999999999998</size>
          </box>
        </geometry>
      </collision>
      <visual name='chassis_fixed_joint_lump__visual_visual'>
        <pose>0 0 0 0 0 0</pose>
        <geometry>
          <mesh>
            <scale>1 1 1</scale>
            <uri>model://simulation/models/vehicle/ads-dv.stl</uri>
          </mesh>
        </geometry>
        <material>
          <diffuse>0 0.25 0.162499994 1</diffuse>
          <ambient>0 0.25 0.162499994 1</ambient>
        </material>
      </visual>
      <sensor name="imu_sensor" type="imu">
        <always_on>1</always_on>
        <update_rate>300</update_rate>
        <visualize>true</visualize>
        <topic>imu</topic>
      </sensor>
    </link>
    <joint name='front_left_wheel_steering_joint' type='revolute'>
      <pose relative_to='chassis'>0.76700000000000002 0.47175 -0.0235 0 0 0</pose>
      <parent>chassis</parent>
      <child>front_left_wheel_steering_link</child>
      <axis>
        <xyz>0 0 1</xyz>
        <limit>
          <lower>-0.42425047713800002</lower>
          <upper>0.42425047713800002</upper>
          <effort>10000</effort>
          <velocity>10000</velocity>
        </limit>
        <dynamics>
          <spring_reference>0</spring_reference>
          <spring_stiffness>0</spring_stiffness>
        </dynamics>
      </axis>
    </joint>
    <link name='front_left_wheel_steering_link'>
      <pose relative_to='front_left_wheel_steering_joint'>0 0 0 0 0 0</pose>
      <inertial>
        <pose>0 0 0 0 0 0</pose>
        <mass>0.001</mass>
        <inertia>
          <ixx>0.001</ixx>
          <ixy>0</ixy>
          <ixz>0</ixz>
          <iyy>0.001</iyy>
          <iyz>0</iyz>
          <izz>0.001</izz>
        </inertia>
      </inertial>
      <visual name='front_left_wheel_steering_link_fixed_joint_lump__steering_link_visual_visual'>
        <pose>0 0 0 0 0 0</pose>
        <geometry>
          <cylinder>
            <length>0.10000000000000001</length>
            <radius>0.029999999999999999</radius>
          </cylinder>
        </geometry>
      </visual>
    </link>
    <joint name='front_left_wheel_joint' type='revolute'>
      <pose relative_to='front_left_wheel_steering_link'>0 0.098250000000000004 0 -1.5707 0 0</pose>
      <parent>front_left_wheel_steering_link</parent>
      <child>front_left_wheel</child>
      <axis>
        <xyz>0 0 1</xyz>
        <limit>
          <lower>-1.7976900000000001e+308</lower>
          <upper>1.7976900000000001e+308</upper>
          <effort>10000</effort>
          <velocity>10000</velocity>
        </limit>
        <dynamics>
          <spring_reference>0</spring_reference>
          <spring_stiffness>0</spring_stiffness>
        </dynamics>
      </axis>
    </joint>
    <link name='front_left_wheel'>
      <pose relative_to='front_left_wheel_joint'>0 0 0 0 0 0</pose>
      <inertial>
        <pose>0 0 0 0 0 0</pose>
        <mass>5.5</mass>
        <inertia>
          <ixx>0.11207078795</ixx>
          <ixy>0</ixy>
          <ixz>0</ixz>
          <iyy>0.11207078795</iyy>
          <iyz>0</iyz>
          <izz>0.1887470134</izz>
        </inertia>
      </inertial>
      <collision name='front_left_wheel_collision'>
        <pose>0 0 0 0 0 0</pose>
        <geometry>
          <cylinder>
            <length>0.19650000000000001</length>
            <radius>0.25750000000000001</radius>
          </cylinder>
        </geometry>
      </collision>
      <visual name='front_left_wheel_fixed_joint_lump__visual_visual'>
        <pose>0 0 0 0 0 0</pose>
        <geometry>
          <cylinder>
            <length>0.19650000000000001</length>
            <radius>0.25750000000000001</radius>
          </cylinder>
        </geometry>
        <material>
          <diffuse>0 0 0 1</diffuse>
          <ambient>0 0 0 1</ambient>
        </material>
      </visual>
    </link>
    <joint name='front_right_wheel_steering_joint' type='revolute'>
      <pose relative_to='chassis'>0.76700000000000002 -0.47175 -0.0235 0 0 0</pose>
      <parent>chassis</parent>
      <child>front_right_wheel_steering_link</child>
      <axis>
        <xyz>0 0 1</xyz>
        <limit>
          <lower>-0.42425047713800002</lower>
          <upper>0.42425047713800002</upper>
          <effort>10000</effort>
          <velocity>10000</velocity>
        </limit>
        <dynamics>
          <spring_reference>0</spring_reference>
          <spring_stiffness>0</spring_stiffness>
        </dynamics>
      </axis>
    </joint>
    <link name='front_right_wheel_steering_link'>
      <pose relative_to='front_right_wheel_steering_joint'>0 0 0 0 0 0</pose>
      <inertial>
        <pose>0 0 0 0 0 0</pose>
        <mass>0.001</mass>
        <inertia>
          <ixx>0.001</ixx>
          <ixy>0</ixy>
          <ixz>0</ixz>
          <iyy>0.001</iyy>
          <iyz>0</iyz>
          <izz>0.001</izz>
        </inertia>
      </inertial>
      <visual name='front_right_wheel_steering_link_fixed_joint_lump__steering_link_visual_visual'>
        <pose>0 0 0 0 0 0</pose>
        <geometry>
          <cylinder>
            <length>0.10000000000000001</length>
            <radius>0.029999999999999999</radius>
          </cylinder>
        </geometry>
      </visual>
    </link>
    <joint name='front_right_wheel_joint' type='revolute'>
      <pose relative_to='front_right_wheel_steering_link'>0 -0.098250000000000004 0 -1.5707 0 0</pose>
      <parent>front_right_wheel_steering_link</parent>
      <child>front_right_wheel</child>
      <axis>
        <xyz>0 0 1</xyz>
        <limit>
          <lower>-1.7976900000000001e+308</lower>
          <upper>1.7976900000000001e+308</upper>
          <effort>10000</effort>
          <velocity>10000</velocity>
        </limit>
        <dynamics>
          <spring_reference>0</spring_reference>
          <spring_stiffness>0</spring_stiffness>
        </dynamics>
      </axis>
    </joint>
    <link name='front_right_wheel'>
      <pose relative_to='front_right_wheel_joint'>0 0 0 0 0 0</pose>
      <inertial>
        <pose>0 0 0 0 0 0</pose>
        <mass>5.5</mass>
        <inertia>
          <ixx>0.11207078795</ixx>
          <ixy>0</ixy>
          <ixz>0</ixz>
          <iyy>0.11207078795</iyy>
          <iyz>0</iyz>
          <izz>0.1887470134</izz>
        </inertia>
      </inertial>
      <collision name='front_right_wheel_collision'>
        <pose>0 0 0 0 0 0</pose>
        <geometry>
          <cylinder>
            <length>0.19650000000000001</length>
            <radius>0.25750000000000001</radius>
          </cylinder>
        </geometry>
      </collision>
      <visual name='front_right_wheel_fixed_joint_lump__visual_visual'>
        <pose>0 0 0 0 0 0</pose>
        <geometry>
          <cylinder>
            <length>0.19650000000000001</length>
            <radius>0.25750000000000001</radius>
          </cylinder>
        </geometry>
        <material>
          <diffuse>0 0 0 1</diffuse>
          <ambient>0 0 0 1</ambient>
        </material>
      </visual>
    </link>
    <joint name='rear_left_wheel_joint' type='revolute'>
      <pose relative_to='chassis'>-0.76700000000000002 0.56999999999999995 -0.0235 -1.5707 0 0</pose>
      <parent>chassis</parent>
      <child>rear_left_wheel</child>
      <axis>
        <xyz>0 0 1</xyz>
        <limit>
          <lower>-1.7976900000000001e+308</lower>
          <upper>1.7976900000000001e+308</upper>
          <effort>10000</effort>
          <velocity>10000</velocity>
        </limit>
        <dynamics>
          <spring_reference>0</spring_reference>
          <spring_stiffness>0</spring_stiffness>
        </dynamics>
      </axis>
    </joint>
    <link name='rear_left_wheel'>
      <pose relative_to='rear_left_wheel_joint'>0 0 0 0 0 0</pose>
      <inertial>
        <pose>0 0 0 0 0 0</pose>
        <mass>5.5</mass>
        <inertia>
          <ixx>0.11207078795</ixx>
          <ixy>0</ixy>
          <ixz>0</ixz>
          <iyy>0.11207078795</iyy>
          <iyz>0</iyz>
          <izz>0.1887470134</izz>
        </inertia>
      </inertial>
      <collision name='rear_left_wheel_collision'>
        <pose>0 0 0 0 0 0</pose>
        <geometry>
          <cylinder>
            <length>0.19650000000000001</length>
            <radius>0.25750000000000001</radius>
          </cylinder>
        </geometry>
      </collision>
      <visual name='rear_left_wheel_fixed_joint_lump__visual_visual'>
        <pose>0 0 0 0 0 0</pose>
        <geometry>
          <cylinder>
            <length>0.19650000000000001</length>
            <radius>0.25750000000000001</radius>
          </cylinder>
        </geometry>
        <material>
          <diffuse>0 0 0 1</diffuse>
          <ambient>0 0 0 1</ambient>
        </material>
      </visual>
    </link>
    <joint name='rear_right_wheel_joint' type='revolute'>
      <pose relative_to='chassis'>-0.76700000000000002 -0.56999999999999995 -0.0235 -1.5707 0 0</pose>
      <parent>chassis</parent>
      <child>rear_right_wheel</child>
      <axis>
        <xyz>0 0 1</xyz>
        <limit>
          <lower>-1.7976900000000001e+308</lower>
          <upper>1.7976900000000001e+308</upper>
          <effort>10000</effort>
          <velocity>10000</velocity>
        </limit>
        <dynamics>
          <spring_reference>0</spring_reference>
          <spring_stiffness>0</spring_stiffness>
        </dynamics>
      </axis>
    </joint>
    <link name='rear_right_wheel'>
      <pose relative_to='rear_right_wheel_joint'>0 0 0 0 0 0</pose>
      <inertial>
        <pose>0 0 0 0 0 0</pose>
        <mass>5.5</mass>
        <inertia>
          <ixx>0.11207078795</ixx>
          <ixy>0</ixy>
          <ixz>0</ixz>
          <iyy>0.11207078795</iyy>
          <iyz>0</iyz>
          <izz>0.1887470134</izz>
        </inertia>
      </inertial>
      <collision name='rear_right_wheel_collision'>
        <pose>0 0 0 0 0 0</pose>
        <geometry>
          <cylinder>
            <length>0.19650000000000001</length>
            <radius>0.25750000000000001</radius>
          </cylinder>
        </geometry>
      </collision>
      <visual name='rear_right_wheel_fixed_joint_lump__visual_visual'>
        <pose>0 0 0 0 0 0</pose>
        <geometry>
          <cylinder>
            <length>0.19650000000000001</length>
            <radius>0.25750000000000001</radius>
          </cylinder>
        </geometry>
        <material>
          <diffuse>0 0 0 1</diffuse>
          <ambient>0 0 0 1</ambient>
        </material>
      </visual>
    </link>
    <joint name='base_to_logical_camera' type='fixed'>
      <pose relative_to='base_link'>0.48649999999999999 0 0.67100000000000004 0 0 0</pose>
      <parent>base_link</parent>
      <child>logical_camera_link</child>
      <axis>
        <dynamics>
          <spring_reference>0</spring_reference>
          <spring_stiffness>0</spring_stiffness>
        </dynamics>
        <xyz>0 0 1</xyz>
        <limit>
          <lower>-inf</lower>
          <upper>inf</upper>
        </limit>
      </axis>
      <physics>
        <ode>
          <limit>
            <cfm>0</cfm>
            <erp>0.20000000000000001</erp>
          </limit>
        </ode>
      </physics>
    </joint>
    <link name='logical_camera_link'>
      <pose relative_to='base_to_logical_camera'>0 0 0 0 0 0</pose>
      <inertial>
        <pose>0 0 0 0 0 0</pose>
        <mass>0.001</mass>
        <inertia>
          <ixx>0.001</ixx>
          <ixy>0</ixy>
          <ixz>0</ixz>
          <iyy>0.001</iyy>
          <iyz>0</iyz>
          <izz>0.001</izz>
        </inertia>
      </inertial>
      <sensor name='logical_camera' type='logical_camera'>
        <update_rate>30</update_rate>
        <topic>logical_camera</topic>
        <always_on>true</always_on>
        <visualize>true</visualize>
        <enable_metrics>true</enable_metrics>
        <logical_camera>
          <near>1.5</near>
          <far>35</far>
          <aspect_ratio>1.333333333333333</aspect_ratio>
          <horizontal_fov>1.22173</horizontal_fov>
        </logical_camera>
        <gz_frame_id>camera_link_optical</gz_frame_id>
      </sensor>
    </link>
    <joint name='base_to_velodyne' type='fixed'>
      <pose relative_to='base_link'>0.52000000000000002 0 0.59945999999999999 0 0 0</pose>
      <parent>base_link</parent>
      <child>velodyne</child>
      <axis>
        <dynamics>
          <spring_reference>0</spring_reference>
          <spring_stiffness>0</spring_stiffness>
        </dynamics>
        <xyz>0 0 1</xyz>
        <limit>
          <lower>-inf</lower>
          <upper>inf</upper>
        </limit>
      </axis>
      <physics>
        <ode>
          <limit>
            <cfm>0</cfm>
            <erp>0.20000000000000001</erp>
          </limit>
        </ode>
      </physics>
    </joint>
    <link name='velodyne'>
      <pose relative_to='base_to_velodyne'>0 0 0 0 0 0</pose>
      <inertial>
        <pose>0 0 0 0 0 0</pose>
        <mass>0.001</mass>
        <inertia>
          <ixx>0.001</ixx>
          <ixy>0</ixy>
          <ixz>0</ixz>
          <iyy>0.001</iyy>
          <iyz>0</iyz>
          <izz>0.001</izz>
        </inertia>
      </inertial>
      <visual name='velodyne_fixed_joint_lump__visual_visual'>
        <pose>0 0 0 0 0 0</pose>
        <geometry>
          <cylinder>
            <length>0.070000000000000007</length>
            <radius>0.050000000000000003</radius>
          </cylinder>
        </geometry>
      </visual>
      <sensor name='VLP-16' type='gpu_lidar'>
        <topic>velodyne</topic>
        <update_rate>10</update_rate>
        <ray>
          <scan>
            <horizontal>
              <samples>1800</samples>
              <resolution>0.0034906590000000001</resolution>
              <min_angle>-0.78539800000000004</min_angle>
              <max_angle>0.78539800000000004</max_angle>
            </horizontal>
            <vertical>
              <samples>16</samples>
              <resolution>0.034906584999999997</resolution>
              <min_angle>-0.26179938000000003</min_angle>
              <max_angle>0.26179939000000002</max_angle>
            </vertical>
          </scan>
          <range>
            <min>1.5</min>
            <max>100</max>
            <resolution>0.002</resolution>
          </range>
        </ray>
        <always_on>true</always_on>
        <visualize>true</visualize>
        <gz_frame_id>velodyne</gz_frame_id>
      </sensor>
    </link>
    <plugin name='gz::sim::systems::AckermannSteering' filename='gz-sim-ackermann-steering-system'>
      <left_joint>front_left_wheel_joint</left_joint>
      <left_joint>rear_left_wheel_joint</left_joint>
      <right_joint>front_right_wheel_joint</right_joint>
      <right_joint>rear_right_wheel_joint</right_joint>
      <left_steering_joint>front_left_wheel_steering_joint</left_steering_joint>
      <right_steering_joint>front_right_wheel_steering_joint</right_steering_joint>
      <kingpin_width>1.0</kingpin_width>
      <steering_limit>0.424250477138</steering_limit>
      <wheel_base>1.534</wheel_base>
      <wheel_separation>1.2</wheel_separation>
      <wheel_radius>0.2575</wheel_radius>
      <topic>cmd_vel</topic>
      <odom_publish_frequency>600</odom_publish_frequency>
      <min_velocity>-10.0</min_velocity>
      <max_velocity>30.0</max_velocity>
      <min_acceleration>-5.2</min_acceleration>
      <max_acceleration>5.2</max_acceleration>
      <frame_id>odom</frame_id>
      <child_frame_id>base_link</child_frame_id>
    </plugin>
    <plugin name='gz::sim::systems::LogicalCamera' filename='gz-sim-logical-camera-system'>
      <render_engine>ogre2</render_engine>
    </plugin>
    <plugin name='gz::sim::systems::JointStatePublisher' filename='gz-sim-joint-state-publisher-system'>
      <topic>/model/ads_dv/joint_state</topic>
    </plugin>
    <plugin filename="gz-sim-imu-system"
        name="gz::sim::systems::Imu">
    </plugin>
  </model>
</sdf>
