<?xml version="1.0" ?>
<robot xmlns:xacro="http://www.ros.org/wiki/xacro" name="ads_dv">

    <!-- Wheels and Joints -->
    <xacro:include filename="$(find simulation)/models/vehicle/wheels.xacro" />

    <link name='chassis'>
        <inertial>
            <mass value="278"/>
            <inertia ixx="14.38" ixy="0" ixz="0" iyy="178.90" iyz="0" izz="175.68"/>
        </inertial>
        <visual name='visual'>
            <origin xyz="0 0 0"/>
            <geometry>
                <mesh filename="package://simulation/models/vehicle/ads-dv.stl" scale="1 1 1"/>
            </geometry>
            <material name="chassis_mat">
                <color rgba="0.0 0.2 0.13 1"/>
            </material>
        </visual>
        <collision name='collision'>
            <geometry>
                <box size="2.7 0.489 0.414"/>
            </geometry>
        </collision>
    </link>

    <!-- Base Link -->
    <link name='base_link'>
        <visual name="visual">
            <geometry>
                <box size="0.01 0.01 0.01"/>
            </geometry>
        </visual>
        <inertial> <!-- Needed to disable lumping -->
            <mass value="0.001"/>
            <inertia ixx="0.001" ixy="0" ixz="0" iyy="0.001" iyz="0" izz="0.001"/>
        </inertial>
    </link>

    <!-- Steering Links and Joints-->
    <link name="front_left_wheel_steering_link">
        <inertial>
            <mass value="0.001"/>
            <inertia ixx="0.001" ixy="0" ixz="0" iyy="0.001" iyz="0" izz="0.001"/>
        </inertial>
        <visual name="steering_link_visual">
            <geometry>
                <cylinder length="0.1" radius="0.03"/>
            </geometry>
        </visual>
    </link>

    <joint name="front_left_wheel_steering_joint" type="revolute">
        <parent link="chassis"/>
        <child link="front_left_wheel_steering_link"/>
        <axis xyz="0 0 1"/>
        <limit lower="-0.424250477138" upper="0.424250477138" velocity="10000" effort="10000"/>
        <origin xyz="0.767 0.47175 -0.0235" rpy="0 0 0"/>
    </joint>

    <link name="front_right_wheel_steering_link">
        <inertial>
            <mass value="0.001"/>
            <inertia ixx="0.001" ixy="0" ixz="0" iyy="0.001" iyz="0" izz="0.001"/>
        </inertial>
        <visual name="steering_link_visual">
            <geometry>
                <cylinder length="0.1" radius="0.03"/>
            </geometry>
        </visual>
    </link>

    <joint name="front_right_wheel_steering_joint" type="revolute">
        <parent link="chassis"/>
        <child link="front_right_wheel_steering_link"/>
        <axis xyz="0 0 1"/>
        <limit lower="-0.424250477138" upper="0.424250477138" velocity="10000" effort="10000"/>
        <origin xyz="0.767 -0.47175 -0.0235" rpy="0 0 0"/>
    </joint>

    <!-- Fixed Joints -->
    <joint name="base_to_camera" type="fixed">
        <parent link="base_link"/>
        <child link="camera_link"/>
        <origin xyz="0.4865 0 0.671" rpy="0 0 0"/>
    </joint>
    <gazebo reference='base_to_camera'>
        <preserveFixedJoint>True</preserveFixedJoint>
    </gazebo>

    <joint name="base_to_velodyne" type="fixed">
        <parent link="base_link"/>
        <child link="velodyne"/>
        <origin xyz="0.52 0 0.59946" rpy="0 0 0"/>
    </joint>
    <gazebo reference='base_to_velodyne'>
        <preserveFixedJoint>True</preserveFixedJoint>
    </gazebo>

    <joint name="base_to_chassis" type="fixed">
        <parent link="base_link"/>
        <child link="chassis"/>
        <origin xyz="0 0 0.307" rpy="0 0 0"/>
    </joint>
    <gazebo reference='base_to_chassis'>
        <preserveFixedJoint>True</preserveFixedJoint>
    </gazebo>

    <!-- Sim (Stereo + Depth + Logical) Camera -->
    <xacro:include filename="$(find simulation)/models/vehicle/sim_camera.xacro" />

    <!-- Velodyne -->
    <xacro:include filename="$(find simulation)/models/vehicle/velodyne.xacro" />

    <!-- Ackermann Steering Plugin -->
    <gazebo>
        <plugin filename="gz-sim-ackermann-steering-system" name="gz::sim::systems::AckermannSteering">
            <left_joint>front_left_wheel_joint</left_joint>
            <left_joint>rear_left_wheel_joint</left_joint>
            <right_joint>front_right_wheel_joint</right_joint>
            <right_joint>rear_right_wheel_joint</right_joint>
            <left_steering_joint>front_left_wheel_steering_joint</left_steering_joint>
            <right_steering_joint>front_right_wheel_steering_joint</right_steering_joint>
            <kingpin_width>1.0</kingpin_width> <!-- or 0.72 idk maybe change it later and see how it affects the simulation -->
            <steering_limit>0.424250477138</steering_limit>
            <wheel_base>1.534</wheel_base>
            <wheel_separation>1.2</wheel_separation>
            <wheel_radius>0.2575</wheel_radius>
            <topic>cmd_vel</topic>
            <odom_publish_frequency>600</odom_publish_frequency>
            <min_velocity>-10.0</min_velocity> <!-- the plugin currently prevents steering to the right if this is set to 0 -->
            <max_velocity>30.0</max_velocity>
            <min_acceleration>-5.2</min_acceleration>
            <max_acceleration>5.2</max_acceleration>
            <frame_id>ads_dv</frame_id>
            <child_frame_id>base_link</child_frame_id>
        </plugin>
        <plugin name="gz::sim::systems::LogicalCamera" filename="gz-sim-logical-camera-system">
            <render_engine>ogre2</render_engine>
        </plugin>
         <plugin name="gz::sim::systems::JointStatePublisher" filename="gz-sim-joint-state-publisher-system">
            <topic>/model/ads_dv/joint_state</topic>
        </plugin>
    </gazebo>
</robot>
