<?xml version="1.0"?>
<robot xmlns:xacro="http://www.ros.org/wiki/xacro" name="vehicle_wheels">

    <!-- Wheel Macro -->
    <xacro:macro name="wheel" params="name parent x y z roll pitch yaw">
        <link name="${name}">
            <visual name="visual">
                <geometry>
                    <cylinder radius="0.2575" length="0.1965"/>
                </geometry>
                <material name="black">
                    <color rgba="0 0 0 1"/>
                </material>
            </visual>
            <collision>
                <geometry>
                    <cylinder radius="0.2575" length="0.1965"/>
                </geometry>
            </collision>
            <inertial>
                <mass value="5.5"/>
                <origin xyz="0 0 0" rpy="0 0 0"/>
                <inertia ixx="0.11207078795000001" ixy="0.0" ixz="0.0" iyy="0.11207078795000001" iyz="0.0" izz="0.1887470134"/>
            </inertial>
        </link>
        <joint name="${name}_joint" type="revolute">
            <parent link="${parent}"/>
            <child link="${name}"/>
            <origin xyz="${x} ${y} ${z}" rpy="${roll} ${pitch} ${yaw}"/>
            <axis xyz="0 0 1"/>
            <limit lower="-1.79769e+308" upper="1.79769e+308" velocity="10000" effort="10000"/>
        </joint>
    
    </xacro:macro>

    <!-- Front Left Wheel -->
    <xacro:wheel name="front_left_wheel" parent="front_left_wheel_steering_link" x="0" y="0.09825" z="0" roll="-1.5707" pitch="0" yaw="0"/>

    <!-- Front Right Wheel -->
    <xacro:wheel name="front_right_wheel" parent="front_right_wheel_steering_link" x="0" y="-0.09825" z="0" roll="-1.5707" pitch="0" yaw="0"/>

    <!-- Rear Left Wheel -->
    <xacro:wheel name="rear_left_wheel" parent="chassis" x="-0.767" y="0.57" z="-0.0235" roll="-1.5707" pitch="0" yaw="0"/>

    <!-- Rear Right Wheel -->
    <xacro:wheel name="rear_right_wheel" parent="chassis" x="-0.767" y="-0.57" z="-0.0235" roll="-1.5707" pitch="0" yaw="0"/>

</robot>
